[2025-04-11T04:18:43.580+0000] {taskinstance.py:1956} INFO - Dependencies all met for dep_context=non-requeueable deps ti=<TaskInstance: proyecto_bigdata.leer_kafka manual__2025-04-11T04:18:40.057265+00:00 [queued]>
[2025-04-11T04:18:43.593+0000] {taskinstance.py:1956} INFO - Dependencies all met for dep_context=requeueable deps ti=<TaskInstance: proyecto_bigdata.leer_kafka manual__2025-04-11T04:18:40.057265+00:00 [queued]>
[2025-04-11T04:18:43.594+0000] {taskinstance.py:2170} INFO - Starting attempt 1 of 1
[2025-04-11T04:18:43.615+0000] {taskinstance.py:2191} INFO - Executing <Task(PythonOperator): leer_kafka> on 2025-04-11 04:18:40.057265+00:00
[2025-04-11T04:18:43.625+0000] {standard_task_runner.py:60} INFO - Started process 2141 to run task
[2025-04-11T04:18:43.629+0000] {standard_task_runner.py:87} INFO - Running: ['***', 'tasks', 'run', 'proyecto_bigdata', 'leer_kafka', 'manual__2025-04-11T04:18:40.057265+00:00', '--job-id', '27', '--raw', '--subdir', 'DAGS_FOLDER/proyecto_bigdata_dag.py', '--cfg-path', '/tmp/tmp14_ex5uu']
[2025-04-11T04:18:43.633+0000] {standard_task_runner.py:88} INFO - Job 27: Subtask leer_kafka
[2025-04-11T04:18:43.705+0000] {task_command.py:423} INFO - Running <TaskInstance: proyecto_bigdata.leer_kafka manual__2025-04-11T04:18:40.057265+00:00 [running]> on host 45536febc47a
[2025-04-11T04:18:43.830+0000] {taskinstance.py:2480} INFO - Exporting env vars: AIRFLOW_CTX_DAG_OWNER='***' AIRFLOW_CTX_DAG_ID='proyecto_bigdata' AIRFLOW_CTX_TASK_ID='leer_kafka' AIRFLOW_CTX_EXECUTION_DATE='2025-04-11T04:18:40.057265+00:00' AIRFLOW_CTX_TRY_NUMBER='1' AIRFLOW_CTX_DAG_RUN_ID='manual__2025-04-11T04:18:40.057265+00:00'
[2025-04-11T04:18:43.833+0000] {logging_mixin.py:188} INFO - ðŸ“¥ Leyendo datos desde predicciones.csv
[2025-04-11T04:18:43.838+0000] {taskinstance.py:2698} ERROR - Task failed with exception
Traceback (most recent call last):
  File "/home/airflow/.local/lib/python3.8/site-packages/airflow/models/taskinstance.py", line 433, in _execute_task
    result = execute_callable(context=context, **execute_callable_kwargs)
  File "/home/airflow/.local/lib/python3.8/site-packages/airflow/operators/python.py", line 199, in execute
    return_value = self.execute_callable()
  File "/home/airflow/.local/lib/python3.8/site-packages/airflow/operators/python.py", line 216, in execute_callable
    return self.python_callable(*self.op_args, **self.op_kwargs)
  File "/opt/airflow/dags/proyecto_bigdata_dag.py", line 13, in leer_datos_kafka
    df = pd.read_csv('/opt/airflow/salidas/predicciones.csv')
  File "/home/airflow/.local/lib/python3.8/site-packages/pandas/io/parsers/readers.py", line 912, in read_csv
    return _read(filepath_or_buffer, kwds)
  File "/home/airflow/.local/lib/python3.8/site-packages/pandas/io/parsers/readers.py", line 577, in _read
    parser = TextFileReader(filepath_or_buffer, **kwds)
  File "/home/airflow/.local/lib/python3.8/site-packages/pandas/io/parsers/readers.py", line 1407, in __init__
    self._engine = self._make_engine(f, self.engine)
  File "/home/airflow/.local/lib/python3.8/site-packages/pandas/io/parsers/readers.py", line 1661, in _make_engine
    self.handles = get_handle(
  File "/home/airflow/.local/lib/python3.8/site-packages/pandas/io/common.py", line 859, in get_handle
    handle = open(
FileNotFoundError: [Errno 2] No such file or directory: '/opt/airflow/salidas/predicciones.csv'
[2025-04-11T04:18:43.859+0000] {taskinstance.py:1138} INFO - Marking task as FAILED. dag_id=proyecto_bigdata, task_id=leer_kafka, execution_date=20250411T041840, start_date=20250411T041843, end_date=20250411T041843
[2025-04-11T04:18:43.875+0000] {standard_task_runner.py:107} ERROR - Failed to execute job 27 for task leer_kafka ([Errno 2] No such file or directory: '/opt/airflow/salidas/predicciones.csv'; 2141)
[2025-04-11T04:18:43.884+0000] {local_task_job_runner.py:234} INFO - Task exited with return code 1
[2025-04-11T04:18:43.917+0000] {taskinstance.py:3280} INFO - 0 downstream tasks scheduled from follow-on schedule check
